<?xml version="1.0" encoding="UTF-8"?>
<testng-results ignored="0" total="4" passed="2" failed="2" skipped="0">
  <reporter-output>
  </reporter-output>
  <suite started-at="2023-03-17T16:29:10 IST" name="Suite" finished-at="2023-03-17T16:29:27 IST" duration-ms="16821">
    <groups>
    </groups>
    <test started-at="2023-03-17T16:29:10 IST" name="ThreeTest" finished-at="2023-03-17T16:29:17 IST" duration-ms="7294">
      <class name="tests.ThreeTest">
        <test-method signature="threeTest()[pri:0, instance:tests.ThreeTest@648c94da]" started-at="2023-03-17T16:29:10 IST" name="threeTest" finished-at="2023-03-17T16:29:17 IST" duration-ms="7193" status="PASS">
          <reporter-output>
          </reporter-output>
        </test-method> <!-- threeTest -->
      </class> <!-- tests.ThreeTest -->
    </test> <!-- ThreeTest -->
    <test started-at="2023-03-17T16:29:10 IST" name="TwoTest" finished-at="2023-03-17T16:29:20 IST" duration-ms="10319">
      <class name="tests.FourTest">
        <test-method signature="FourTest()[pri:0, instance:tests.FourTest@7331196b]" started-at="2023-03-17T16:29:10 IST" name="FourTest" finished-at="2023-03-17T16:29:20 IST" duration-ms="9468" status="FAIL">
          <exception class="java.lang.AssertionError">
            <message>
              <![CDATA[expected [true] but found [false]]]>
            </message>
            <full-stacktrace>
              <![CDATA[java.lang.AssertionError: expected [true] but found [false]
at org.testng.Assert.fail(Assert.java:110)
at org.testng.Assert.failNotEquals(Assert.java:1577)
at org.testng.Assert.assertTrue(Assert.java:56)
at org.testng.Assert.assertTrue(Assert.java:66)
at tests.FourTest.FourTest(FourTest.java:22)
at java.base/jdk.internal.reflect.NativeMethodAccessorImpl.invoke0(Native Method)
at java.base/jdk.internal.reflect.NativeMethodAccessorImpl.invoke(NativeMethodAccessorImpl.java:77)
at java.base/jdk.internal.reflect.DelegatingMethodAccessorImpl.invoke(DelegatingMethodAccessorImpl.java:43)
at java.base/java.lang.reflect.Method.invoke(Method.java:568)
at org.testng.internal.invokers.MethodInvocationHelper.invokeMethod(MethodInvocationHelper.java:139)
at org.testng.internal.invokers.TestInvoker.invokeMethod(TestInvoker.java:677)
at org.testng.internal.invokers.TestInvoker.invokeTestMethod(TestInvoker.java:221)
at org.testng.internal.invokers.MethodRunner.runInSequence(MethodRunner.java:50)
at org.testng.internal.invokers.TestInvoker$MethodInvocationAgent.invoke(TestInvoker.java:969)
at org.testng.internal.invokers.TestInvoker.invokeTestMethods(TestInvoker.java:194)
at org.testng.internal.invokers.TestMethodWorker.invokeTestMethods(TestMethodWorker.java:148)
at org.testng.internal.invokers.TestMethodWorker.run(TestMethodWorker.java:128)
at java.base/java.util.ArrayList.forEach(ArrayList.java:1511)
at org.testng.TestRunner.privateRun(TestRunner.java:829)
at org.testng.TestRunner.run(TestRunner.java:602)
at org.testng.SuiteRunner.runTest(SuiteRunner.java:437)
at org.testng.SuiteRunner$SuiteWorker.run(SuiteRunner.java:475)
at org.testng.internal.thread.ThreadUtil.lambda$execute$0(ThreadUtil.java:58)
at java.base/java.util.concurrent.FutureTask.run(FutureTask.java:264)
at java.base/java.util.concurrent.ThreadPoolExecutor.runWorker(ThreadPoolExecutor.java:1136)
at java.base/java.util.concurrent.ThreadPoolExecutor$Worker.run(ThreadPoolExecutor.java:635)
at java.base/java.lang.Thread.run(Thread.java:833)
]]>
            </full-stacktrace>
          </exception> <!-- java.lang.AssertionError -->
          <reporter-output>
          </reporter-output>
        </test-method> <!-- FourTest -->
      </class> <!-- tests.FourTest -->
    </test> <!-- TwoTest -->
    <test started-at="2023-03-17T16:29:19 IST" name="FourTest" finished-at="2023-03-17T16:29:24 IST" duration-ms="5059">
      <class name="tests.FourTest">
        <test-method signature="FourTest()[pri:0, instance:tests.FourTest@51acdf2e]" started-at="2023-03-17T16:29:19 IST" name="FourTest" finished-at="2023-03-17T16:29:23 IST" duration-ms="4528" status="FAIL">
          <exception class="java.lang.AssertionError">
            <message>
              <![CDATA[expected [true] but found [false]]]>
            </message>
            <full-stacktrace>
              <![CDATA[java.lang.AssertionError: expected [true] but found [false]
at org.testng.Assert.fail(Assert.java:110)
at org.testng.Assert.failNotEquals(Assert.java:1577)
at org.testng.Assert.assertTrue(Assert.java:56)
at org.testng.Assert.assertTrue(Assert.java:66)
at tests.FourTest.FourTest(FourTest.java:22)
at java.base/jdk.internal.reflect.NativeMethodAccessorImpl.invoke0(Native Method)
at java.base/jdk.internal.reflect.NativeMethodAccessorImpl.invoke(NativeMethodAccessorImpl.java:77)
at java.base/jdk.internal.reflect.DelegatingMethodAccessorImpl.invoke(DelegatingMethodAccessorImpl.java:43)
at java.base/java.lang.reflect.Method.invoke(Method.java:568)
at org.testng.internal.invokers.MethodInvocationHelper.invokeMethod(MethodInvocationHelper.java:139)
at org.testng.internal.invokers.TestInvoker.invokeMethod(TestInvoker.java:677)
at org.testng.internal.invokers.TestInvoker.invokeTestMethod(TestInvoker.java:221)
at org.testng.internal.invokers.MethodRunner.runInSequence(MethodRunner.java:50)
at org.testng.internal.invokers.TestInvoker$MethodInvocationAgent.invoke(TestInvoker.java:969)
at org.testng.internal.invokers.TestInvoker.invokeTestMethods(TestInvoker.java:194)
at org.testng.internal.invokers.TestMethodWorker.invokeTestMethods(TestMethodWorker.java:148)
at org.testng.internal.invokers.TestMethodWorker.run(TestMethodWorker.java:128)
at java.base/java.util.ArrayList.forEach(ArrayList.java:1511)
at org.testng.TestRunner.privateRun(TestRunner.java:829)
at org.testng.TestRunner.run(TestRunner.java:602)
at org.testng.SuiteRunner.runTest(SuiteRunner.java:437)
at org.testng.SuiteRunner$SuiteWorker.run(SuiteRunner.java:475)
at org.testng.internal.thread.ThreadUtil.lambda$execute$0(ThreadUtil.java:58)
at java.base/java.util.concurrent.FutureTask.run(FutureTask.java:264)
at java.base/java.util.concurrent.ThreadPoolExecutor.runWorker(ThreadPoolExecutor.java:1136)
at java.base/java.util.concurrent.ThreadPoolExecutor$Worker.run(ThreadPoolExecutor.java:635)
at java.base/java.lang.Thread.run(Thread.java:833)
]]>
            </full-stacktrace>
          </exception> <!-- java.lang.AssertionError -->
          <reporter-output>
          </reporter-output>
        </test-method> <!-- FourTest -->
      </class> <!-- tests.FourTest -->
    </test> <!-- FourTest -->
    <test started-at="2023-03-17T16:29:10 IST" name="LOginTest" finished-at="2023-03-17T16:29:27 IST" duration-ms="16821">
      <class name="tests.LoginTest">
        <test-method signature="login()[pri:0, instance:tests.LoginTest@2ea6e30c]" started-at="2023-03-17T16:29:10 IST" name="login" finished-at="2023-03-17T16:29:25 IST" duration-ms="15128" status="PASS">
          <reporter-output>
          </reporter-output>
        </test-method> <!-- login -->
        <test-method is-config="true" signature="teardown()[pri:0, instance:tests.LoginTest@2ea6e30c]" started-at="2023-03-17T16:29:25 IST" name="teardown" finished-at="2023-03-17T16:29:27 IST" duration-ms="1621" status="PASS">
          <reporter-output>
          </reporter-output>
        </test-method> <!-- teardown -->
      </class> <!-- tests.LoginTest -->
    </test> <!-- LOginTest -->
  </suite> <!-- Suite -->
</testng-results>
